<?xml version="1.0" encoding="utf-8"?>
<!-- This URDF was automatically created by SolidWorks to URDF Exporter! Originally created by Stephen Brawner (brawner@gmail.com) 
     Commit Version: 1.6.0-4-g7f85cfe  Build Version: 1.6.7995.38578
     For more information, please see http://wiki.ros.org/sw_urdf_exporter -->
<robot
  name="robot_description_v7">
  <link
    name="base_link">
    <inertial>
      <origin
        xyz="0.0283696678283404 -0.00533876695224345 0.0709761613282027"
        rpy="0 0 0" />
      <mass
        value="9.39619068658661" />
      <inertia
        ixx="0.0377507857214502"
        ixy="-0.00025260952951414"
        ixz="0.000472445125057065"
        iyy="0.0596692828570826"
        iyz="-6.23805138011396E-07"
        izz="0.0745531132620247" />
    </inertial>
    <visual>
      <origin
        xyz="0 0 0"
        rpy="0 0 0" />
      <geometry>
        <mesh
          filename="package://robot_description_v7/meshes/base_link.STL" />
      </geometry>
      <material
        name="">
        <color
          rgba="0.752941176470588 0.752941176470588 0.752941176470588 1" />
      </material>
    </visual>
    <collision>
      <origin
        xyz="0 0 0"
        rpy="0 0 0" />
      <geometry>
        <mesh
          filename="package://robot_description_v7/meshes/base_link.STL" />
      </geometry>
    </collision>
  </link>
  <link
    name="lidar_link">
    <inertial>
      <origin
        xyz="0.0148383171366355 0.000447683430938262 -0.0211536208206848"
        rpy="0 0 0" />
      <mass
        value="0.0312409127406477" />
      <inertia
        ixx="8.88026370810989E-06"
        ixy="-1.77664494330293E-07"
        ixz="1.1302767991708E-07"
        iyy="1.44910018205434E-05"
        iyz="3.4607611499615E-08"
        izz="2.25289099520269E-05" />
    </inertial>
    <visual>
      <origin
        xyz="0 0 0"
        rpy="0 0 0" />
      <geometry>
        <mesh
          filename="package://robot_description_v7/meshes/lidar_link.STL" />
      </geometry>
      <material
        name="">
        <color
          rgba="0.792156862745098 0.819607843137255 0.933333333333333 1" />
      </material>
    </visual>
    <collision>
      <origin
        xyz="0 0 0"
        rpy="0 0 0" />
      <geometry>
        <mesh
          filename="package://robot_description_v7/meshes/lidar_link.STL" />
      </geometry>
    </collision>
  </link>
  <joint
    name="lidar"
    type="fixed">
    <origin
      xyz="0.155666725643582 0.00112777065633451 0.146099999998099"
      rpy="0 0 0" />
    <parent
      link="base_link" />
    <child
      link="lidar_link" />
    <axis
      xyz="0 0 0" />
  </joint>
  <link
    name="imu_link">
    <inertial>
      <origin
        xyz="-0.0126528450668609 -0.0126936660240067 -0.00550000000000006"
        rpy="0 0 0" />
      <mass
        value="0.00712049275087492" />
      <inertia
        ixx="4.56098515619147E-07"
        ixy="9.31843930741966E-09"
        ixz="-1.09369951241934E-22"
        iyy="4.56158545750304E-07"
        iyz="-1.2528223878318E-21"
        izz="7.68660457560139E-07" />
    </inertial>
    <visual>
      <origin
        xyz="0 0 0"
        rpy="0 0 0" />
      <geometry>
        <mesh
          filename="package://robot_description_v7/meshes/imu_link.STL" />
      </geometry>
      <material
        name="">
        <color
          rgba="0.792156862745098 0.819607843137255 0.933333333333333 1" />
      </material>
    </visual>
    <collision>
      <origin
        xyz="0 0 0"
        rpy="0 0 0" />
      <geometry>
        <mesh
          filename="package://robot_description_v7/meshes/imu_link.STL" />
      </geometry>
    </collision>
  </link>
  <joint
    name="imu"
    type="fixed">
    <origin
      xyz="0.15399 -0.085457 0.041"
      rpy="0 0 0" />
    <parent
      link="base_link" />
    <child
      link="imu_link" />
    <axis
      xyz="0 0 0" />
  </joint>
  <link
    name="right_wheel_link">
    <inertial>
      <origin
        xyz="0.000243587829778402 -0.0295000990455643 8.01160804364542E-11"
        rpy="0 0 0" />
      <mass
        value="0.98170665090244" />
      <inertia
        ixx="0.00165298851738423"
        ixy="-1.01249151821569E-05"
        ixz="1.30270760846625E-08"
        iyy="0.00287861950962306"
        iyz="5.32883625868118E-10"
        izz="0.00165292257365774" />
    </inertial>
    <visual>
      <origin
        xyz="0 0 0"
        rpy="0 0 0" />
      <geometry>
        <mesh
          filename="package://robot_description_v7/meshes/right_wheel_link.STL" />
      </geometry>
      <material
        name="">
        <color
          rgba="0.2 0.2 0.2 1" />
      </material>
    </visual>
    <collision>
      <origin
        xyz="0 0 0"
        rpy="0 0 0" />
      <geometry>
        <mesh
          filename="package://robot_description_v7/meshes/right_wheel_link.STL" />
      </geometry>
    </collision>
  </link>
  <joint
    name="right_wheel"
    type="continuous">
    <origin
      xyz="0.0015756 -0.17502 0.015"
      rpy="0 0 0" />
    <parent
      link="base_link" />
    <child
      link="right_wheel_link" />
    <axis
      xyz="-0.0082569 0.99997 0" />
  </joint>
  <link
    name="left_wheel_link">
    <inertial>
      <origin
        xyz="-0.000243587829778624 0.0295000990455639 8.01149702134296E-11"
        rpy="0 0 0" />
      <mass
        value="0.981706650902443" />
      <inertia
        ixx="0.00165299120834847"
        ixy="-1.01249109871006E-05"
        ixz="-1.44984115092976E-08"
        iyy="0.00287861950901393"
        iyz="7.25004217282431E-11"
        izz="0.00165291988234476" />
    </inertial>
    <visual>
      <origin
        xyz="0 0 0"
        rpy="0 0 0" />
      <geometry>
        <mesh
          filename="package://robot_description_v7/meshes/left_wheel_link.STL" />
      </geometry>
      <material
        name="">
        <color
          rgba="0.2 0.2 0.2 1" />
      </material>
    </visual>
    <collision>
      <origin
        xyz="0 0 0"
        rpy="0 0 0" />
      <geometry>
        <mesh
          filename="package://robot_description_v7/meshes/left_wheel_link.STL" />
      </geometry>
    </collision>
  </link>
  <joint
    name="left_wheel"
    type="continuous">
    <origin
      xyz="-0.0013143 0.17497 0.015"
      rpy="0 0 0" />
    <parent
      link="base_link" />
    <child
      link="left_wheel_link" />
    <axis
      xyz="0.0082569 -0.99997 0" />
  </joint>
  <link
    name="camera_link">
    <inertial>
      <origin
        xyz="-0.0286974043856941 -0.00315323141543045 -0.0069642717036188"
        rpy="0 0 0" />
      <mass
        value="0.646454884722171" />
      <inertia
        ixx="0.00284238273162732"
        ixy="1.87273045722636E-05"
        ixz="1.48075090926775E-07"
        iyy="0.000263758634501103"
        iyz="-3.33736129073467E-08"
        izz="0.00296274058967308" />
    </inertial>
    <visual>
      <origin
        xyz="0 0 0"
        rpy="0 0 0" />
      <geometry>
        <mesh
          filename="package://robot_description_v7/meshes/camera_link.STL" />
      </geometry>
      <material
        name="">
        <color
          rgba="0.752941176470588 0.752941176470588 0.752941176470588 1" />
      </material>
    </visual>
    <collision>
      <origin
        xyz="0 0 0"
        rpy="0 0 0" />
      <geometry>
        <mesh
          filename="package://robot_description_v7/meshes/camera_link.STL" />
      </geometry>
    </collision>
  </link>
  <joint
    name="cam"
    type="fixed">
    <origin
      xyz="0.264952270554911 0.00535821231736117 0.284425164615102"
      rpy="0 0 0" />
    <parent
      link="base_link" />
    <child
      link="camera_link" />
    <axis
      xyz="0 0 0" />
  </joint>
</robot>