<?xml version="1.0" encoding="utf-8"?>
<!-- This URDF was automatically created by SolidWorks to URDF Exporter! Originally created by Stephen Brawner (brawner@gmail.com) 
     Commit Version: 1.6.0-4-g7f85cfe  Build Version: 1.6.7995.38578
     For more information, please see http://wiki.ros.org/sw_urdf_exporter -->
<robot
  name="robot_description_v5">
  <link
    name="base_link">
    <inertial>
      <origin
        xyz="0.0507445172710426 -0.0044726634619881 0.157766608561125"
        rpy="0 0 0" />
      <mass
        value="10.7166420111859" />
      <inertia
        ixx="0.0548107334182251"
        ixy="-0.000231377846896314"
        ixz="0.00137449669173955"
        iyy="0.0741557807242815"
        iyz="6.76879370699756E-06"
        izz="0.0792927894788588" />
    </inertial>
    <visual>
      <origin
        xyz="0 0 0"
        rpy="0 0 0" />
      <geometry>
        <mesh
          filename="package://robot_description_v5/meshes/base_link.STL" />
      </geometry>
      <material
        name="">
        <color
          rgba="0.752941176470588 0.752941176470588 0.752941176470588 1" />
      </material>
    </visual>
    <collision>
      <origin
        xyz="0 0 0"
        rpy="0 0 0" />
      <geometry>
        <mesh
          filename="package://robot_description_v5/meshes/base_link.STL" />
      </geometry>
    </collision>
  </link>
  <link
    name="lidar_link">
    <inertial>
      <origin
        xyz="0.0148383171368258 0.000447683431068324 -0.0211536208181387"
        rpy="0 0 0" />
      <mass
        value="0.0312409127404856" />
      <inertia
        ixx="8.88026370808525E-06"
        ixy="-1.77664494264026E-07"
        ixz="1.13027679908932E-07"
        iyy="1.44910018203742E-05"
        iyz="3.4607611495907E-08"
        izz="2.25289099518335E-05" />
    </inertial>
    <visual>
      <origin
        xyz="0 0 0"
        rpy="0 0 0" />
      <geometry>
        <mesh
          filename="package://robot_description_v5/meshes/lidar_link.STL" />
      </geometry>
      <material
        name="">
        <color
          rgba="0.792156862745098 0.819607843137255 0.933333333333333 1" />
      </material>
    </visual>
    <collision>
      <origin
        xyz="0 0 0"
        rpy="0 0 0" />
      <geometry>
        <mesh
          filename="package://robot_description_v5/meshes/lidar_link.STL" />
      </geometry>
    </collision>
  </link>
  <joint
    name="lidar"
    type="fixed">
    <origin
      xyz="0.155666725643582 0.00112777065633451 0.146099999998099"
      rpy="0 0 0" />
    <parent
      link="base_link" />
    <child
      link="lidar_link" />
    <axis
      xyz="0 0 0" />
  </joint>
  <link
    name="imu_link">
    <inertial>
      <origin
        xyz="-0.000128980117747979 -0.000191495597993169 -0.00384070509348666"
        rpy="0 0 0" />
      <mass
        value="0.000999898118986841" />
      <inertia
        ixx="2.50447716935416E-08"
        ixy="1.03965056246922E-10"
        ixz="-2.68560481635183E-14"
        iyy="1.24513535508531E-08"
        iyz="-1.18565423483644E-14"
        izz="3.06376353115898E-08" />
    </inertial>
    <visual>
      <origin
        xyz="0 0 0"
        rpy="0 0 0" />
      <geometry>
        <mesh
          filename="package://robot_description_v5/meshes/imu_link.STL" />
      </geometry>
      <material
        name="">
        <color
          rgba="0.792156862745098 0.819607843137255 0.933333333333333 1" />
      </material>
    </visual>
    <collision>
      <origin
        xyz="0 0 0"
        rpy="0 0 0" />
      <geometry>
        <mesh
          filename="package://robot_description_v5/meshes/imu_link.STL" />
      </geometry>
    </collision>
  </link>
  <joint
    name="imu"
    type="fixed">
    <origin
      xyz="0.126428933055049 -0.100523077234269 0.0330200000034927"
      rpy="0 0 0" />
    <parent
      link="base_link" />
    <child
      link="imu_link" />
    <axis
      xyz="0 0 0" />
  </joint>
  <link
    name="right_wheel_link">
    <inertial>
      <origin
        xyz="0.000243587829777514 -0.0295000990455644 8.01158028806981E-11"
        rpy="0 0 0" />
      <mass
        value="0.981706650902444" />
      <inertia
        ixx="0.0016529887582961"
        ixy="-1.01208993064446E-05"
        ixz="-1.81686206751414E-09"
        iyy="0.00287861061005825"
        iyz="-1.35675327362515E-11"
        izz="0.00165291235980834" />
    </inertial>
    <visual>
      <origin
        xyz="0 0 0"
        rpy="0 0 0" />
      <geometry>
        <mesh
          filename="package://robot_description_v5/meshes/right_wheel_link.STL" />
      </geometry>
      <material
        name="">
        <color
          rgba="0.2 0.2 0.2 1" />
      </material>
    </visual>
    <collision>
      <origin
        xyz="0 0 0"
        rpy="0 0 0" />
      <geometry>
        <mesh
          filename="package://robot_description_v5/meshes/right_wheel_link.STL" />
      </geometry>
    </collision>
  </link>
  <joint
    name="right_wheel"
    type="continuous">
    <origin
      xyz="0.00157556970077088 -0.175020257687692 0.0150000000042174"
      rpy="0 0 0" />
    <parent
      link="base_link" />
    <child
      link="right_wheel_link" />
    <axis
      xyz="-0.00825691107326283 0.999965911128739 0" />
  </joint>
  <link
    name="left_wheel_link">
    <inertial>
      <origin
        xyz="-0.000243587829778624 0.0295000990455639 8.01149702134296E-11"
        rpy="0 0 0" />
      <mass
        value="0.981706650902443" />
      <inertia
        ixx="0.00165299120834847"
        ixy="-1.01249109871006E-05"
        ixz="-1.44984115092567E-08"
        iyy="0.00287861950901393"
        iyz="7.25004217107899E-11"
        izz="0.00165291988234476" />
    </inertial>
    <visual>
      <origin
        xyz="0 0 0"
        rpy="0 0 0" />
      <geometry>
        <mesh
          filename="package://robot_description_v5/meshes/left_wheel_link.STL" />
      </geometry>
      <material
        name="">
        <color
          rgba="0.2 0.2 0.2 1" />
      </material>
    </visual>
    <collision>
      <origin
        xyz="0 0 0"
        rpy="0 0 0" />
      <geometry>
        <mesh
          filename="package://robot_description_v5/meshes/left_wheel_link.STL" />
      </geometry>
    </collision>
  </link>
  <joint
    name="left_wheel"
    type="continuous">
    <origin
      xyz="-0.00131434917487327 0.174967811207364 0.0150000000042175"
      rpy="0 0 0" />
    <parent
      link="base_link" />
    <child
      link="left_wheel_link" />
    <axis
      xyz="0.00825691107326281 -0.999965911128739 0" />
  </joint>
  <link
    name="camera_link">
    <inertial>
      <origin
        xyz="-0.0286974043856941 -0.00315323141543045 -0.0069642717036188"
        rpy="0 0 0" />
      <mass
        value="0.646454884722171" />
      <inertia
        ixx="0.00284238273162732"
        ixy="1.87273045722636E-05"
        ixz="1.4807509092678E-07"
        iyy="0.000263758634501103"
        iyz="-3.33736129073289E-08"
        izz="0.00296274058967308" />
    </inertial>
    <visual>
      <origin
        xyz="0 0 0"
        rpy="0 0 0" />
      <geometry>
        <mesh
          filename="package://robot_description_v5/meshes/camera_link.STL" />
      </geometry>
      <material
        name="">
        <color
          rgba="0.752941176470588 0.752941176470588 0.752941176470588 1" />
      </material>
    </visual>
    <collision>
      <origin
        xyz="0 0 0"
        rpy="0 0 0" />
      <geometry>
        <mesh
          filename="package://robot_description_v5/meshes/camera_link.STL" />
      </geometry>
    </collision>
  </link>
  <joint
    name="cam"
    type="fixed">
    <origin
      xyz="0.264952270554911 0.00535821231736117 0.284425164615102"
      rpy="0 0 0" />
    <parent
      link="base_link" />
    <child
      link="camera_link" />
    <axis
      xyz="0 0 0" />
  </joint>
</robot>